[34m[1mwandb[39m[22m: [32m[41mERROR[39m[49m Permission denied to access vimandika-21-university-of-moratuwa/huggingface/bqz48kv1
Traceback (most recent call last):
  File "C:\Users\Isara Liyanage\AppData\Local\Programs\Python\Python312\Lib\site-packages\wandb\sdk\lib\retry.py", line 131, in __call__
    result = self._call_fn(*args, **kwargs)
             ^^^^^^^^^^^^^^^^^^^^^^^^^^^^^^
  File "C:\Users\Isara Liyanage\AppData\Local\Programs\Python\Python312\Lib\site-packages\wandb\apis\public\api.py", line 70, in execute
    return self._client.execute(*args, **kwargs)
           ^^^^^^^^^^^^^^^^^^^^^^^^^^^^^^^^^^^^^
  File "C:\Users\Isara Liyanage\AppData\Local\Programs\Python\Python312\Lib\site-packages\wandb\vendor\gql-0.2.0\wandb_gql\client.py", line 52, in execute
    result = self._get_result(document, *args, **kwargs)
             ^^^^^^^^^^^^^^^^^^^^^^^^^^^^^^^^^^^^^^^^^^^
  File "C:\Users\Isara Liyanage\AppData\Local\Programs\Python\Python312\Lib\site-packages\wandb\vendor\gql-0.2.0\wandb_gql\client.py", line 60, in _get_result
    return self.transport.execute(document, *args, **kwargs)
           ^^^^^^^^^^^^^^^^^^^^^^^^^^^^^^^^^^^^^^^^^^^^^^^^^
  File "C:\Users\Isara Liyanage\AppData\Local\Programs\Python\Python312\Lib\site-packages\wandb\sdk\lib\gql_request.py", line 59, in execute
    request.raise_for_status()
  File "C:\Users\Isara Liyanage\AppData\Local\Programs\Python\Python312\Lib\site-packages\requests\models.py", line 1021, in raise_for_status
    raise HTTPError(http_error_msg, response=self)
requests.exceptions.HTTPError: 404 Client Error: Not Found for url: https://api.wandb.ai/graphql
During handling of the above exception, another exception occurred:
Traceback (most recent call last):
  File "c:\Users\Isara Liyanage\Documents\GitHub\HealthBot_Plus\HealthBot Plus App\backend\app.py", line 76, in <module>
    artifact = run.use_artifact('swin-tiny-patch4-window7-224-finetuned-skin-cancer:v0', type='model')
               ^^^^^^^^^^^^^^^^^^^^^^^^^^^^^^^^^^^^^^^^^^^^^^^^^^^^^^^^^^^^^^^^^^^^^^^^^^^^^^^^^^^^^^^
  File "C:\Users\Isara Liyanage\AppData\Local\Programs\Python\Python312\Lib\site-packages\wandb\sdk\wandb_run.py", line 401, in wrapper_fn
    return func(self, *args, **kwargs)
           ^^^^^^^^^^^^^^^^^^^^^^^^^^^
  File "C:\Users\Isara Liyanage\AppData\Local\Programs\Python\Python312\Lib\site-packages\wandb\sdk\wandb_run.py", line 391, in wrapper
    return func(self, *args, **kwargs)
           ^^^^^^^^^^^^^^^^^^^^^^^^^^^
  File "C:\Users\Isara Liyanage\AppData\Local\Programs\Python\Python312\Lib\site-packages\wandb\sdk\wandb_run.py", line 3024, in use_artifact
    artifact = public_api.artifact(type=type, name=name)
               ^^^^^^^^^^^^^^^^^^^^^^^^^^^^^^^^^^^^^^^^^
  File "C:\Users\Isara Liyanage\AppData\Local\Programs\Python\Python312\Lib\site-packages\wandb\apis\normalize.py", line 73, in wrapper
    raise err
  File "C:\Users\Isara Liyanage\AppData\Local\Programs\Python\Python312\Lib\site-packages\wandb\apis\normalize.py", line 41, in wrapper
    return func(*args, **kwargs)
           ^^^^^^^^^^^^^^^^^^^^^
  File "C:\Users\Isara Liyanage\AppData\Local\Programs\Python\Python312\Lib\site-packages\wandb\apis\public\api.py", line 1034, in artifact
    artifact = wandb.Artifact._from_name(
               ^^^^^^^^^^^^^^^^^^^^^^^^^^
  File "C:\Users\Isara Liyanage\AppData\Local\Programs\Python\Python312\Lib\site-packages\wandb\sdk\artifacts\artifact.py", line 258, in _from_name
    response = client.execute(
               ^^^^^^^^^^^^^^^
  File "C:\Users\Isara Liyanage\AppData\Local\Programs\Python\Python312\Lib\site-packages\wandb\sdk\lib\retry.py", line 212, in wrapped_fn
    return retrier(*args, **kargs)
           ^^^^^^^^^^^^^^^^^^^^^^^
  File "C:\Users\Isara Liyanage\AppData\Local\Programs\Python\Python312\Lib\site-packages\wandb\sdk\lib\retry.py", line 147, in __call__
    retry_timedelta_triggered = check_retry_fn(e)
                                ^^^^^^^^^^^^^^^^^
  File "C:\Users\Isara Liyanage\AppData\Local\Programs\Python\Python312\Lib\site-packages\wandb\util.py", line 908, in no_retry_auth
    raise CommError(f"Permission denied to access {wandb.run.path}")
wandb.errors.CommError: Permission denied to access vimandika-21-university-of-moratuwa/huggingface/bqz48kv1